### 基本用法

```js
const p = new Promise((resolve, reject) => {
    //do something
   	 if (/* 异步操作成功 */){
        resolve(value);
      } else {
        reject(error);
      }
})

p.then((value) => {
    //resove 成功执行这里
}, (error) => {
    //reject 错误执行这里
})

//或者改成下面写法			
p.then((res) => {
    //resolved时调用
}).catch((error) => {
    //rejected时调用
})

//只要在以下的函数中return返回值，都可以使用then继续执行。return的值都会被当成resolved成功传递下去
p.then(res => {
    return 111		//resolved形式被下面的then继续执行
}).then(res => {
    console.log(res)	//111	resolved
})
p.catch(error => {
    return 222	//resolved形式被下面的then继续执行
}).then(res => {
    console.log(res)	//222	resolved
})
```

1. Promise 新建后就会立即执行。

2. 注意，调用`resolve`或`reject`并不会终结 Promise 的参数函数的执行。这是因为立即 resolved 的 Promise 是在本轮事件循环的末尾执行，总是晚于本轮循环的同步任务。

```javascript
new Promise((resolve, reject) => {
  resolve(1);   //其实是在事件循环的末尾执行
  console.log(2);
}).then(r => {
  console.log(r);
});
// 2
// 1
```

一般来说，调用`resolve`或`reject`以后，Promise 的使命就完成了，后继操作应该放到`then`方法里面，而不应该直接写在`resolve`或`reject`的后面。所以，最好在它们前面加上`return`语句，这样就不会有意外。

```javascript
new Promise((resolve, reject) => {
  return resolve(1);
  // 后面的语句不会执行
  console.log(2);
})
```



### Promise.prototype.then()

Promise 实例具有`then`方法，也就是说，`then`方法是定义在原型对象`Promise.prototype`上的。

**`then`方法返回的是一个新的`Promise`实例（注意，不是原来那个`Promise`实例）**。因此可以采用链式写法，即`then`方法后面再调用另一个`then`方法。

```javascript
getJSON("/posts.json").then(json => {
  return json.post;		//注意需要return 返回一个新的Promise实例
}).then(post => {
  // ...
});
```



### Promise.prototype.catch()

**切记抛出的是异步错误**。

`Promise.prototype.catch`方法是`.then(null, rejection)`的别名，用于指定发生错误时的回调函数。**catch方法返回的也是一个新的Promise实例，所以后面还能接着调用`then`方法。**

关于Promise中的catch方法，其实都是当**抛出异步错误**，可以用`catch`方法捕获，就像下面这样写

```javascript
database.users.get({id: userId})
.then(...)
.catch(...)
```

但是`database.users.get()`可能还会抛出同步错误（比如数据库连接错误，具体要看实现方法），此时用`try...catch`去捕获。

```javascript
try {
  database.users.get({id: userId})
  .then(...)
  .catch(...)
} catch (e) {
  // ...
}
```

```javascript
getJSON('/posts.json').then(function(posts) {
  // ...
}).catch(function(error) {
  // 处理 getJSON 和 前一个回调函数运行时发生的错误
  console.log('发生错误！', error);
  return 222	//返回一个新的Promise实例
}).then(res => {
    console.log(res)	//222
})
```

另外，`then`方法指定的回调函数，如果运行中抛出错误，也会被`catch`方法捕获。

```javascript
const promise = new Promise(function(resolve, reject) {
  throw new Error('test');
});
promise.catch(function(error) {
  console.log(error);
});
// Error: test

//注意，上面的写法与下面两种写法是等价的。

// 写法一
const promise = new Promise(function(resolve, reject) {
  try {
    throw new Error('test');
  } catch(e) {
    reject(e);
  }
});
promise.catch(function(error) {
  console.log(error);
});

// 写法二
const promise = new Promise(function(resolve, reject) {
  reject(new Error('test'));
});
promise.catch(function(error) {
  console.log(error);
});
```

如果 Promise 状态已经变成`resolved`，再抛出错误是无效的。

```javascript
const promise = new Promise(function(resolve, reject) {
  resolve('ok');		//即使这句话是在事件循环末尾执行，先执行下面这句，但还是无法抛出错误了
  throw new Error('test');
});
promise
  .then(function(value) { console.log(value) })
  .catch(function(error) { console.log(error) });
// ok
```

Promise 在`resolve`语句后面，再抛出错误，不会被捕获，等于没有抛出。因为 Promise 的状态一旦改变，就永久保持该状态，不会再变了。

Promise 对象的错误具有“冒泡”性质，会一直向后传递，直到被捕获为止。也就是说，错误总是会被下一个`catch`语句捕获。

```javascript
getJSON('/post/1.json').then(function(post) {
  return getJSON(post.commentURL);
}).then(function(comments) {
  // some code
}).catch(function(error) {
  // 处理前面三个Promise只要有一个产生错误，就会被捕获
});
```

Promise 内部的错误不会影响到 Promise 外部的代码，通俗的说法就是“Promise 会吃掉错误”。比如Promise 内部的一些语法错误，导致报错，不会中断浏览器执行，其他代码还会执行，只是控制台上出现了报错。

一般总是建议，Promise 对象后面要跟`catch`方法，这样可以处理 Promise 内部发生的错误。`catch`方法返回的还是一个 Promise 对象，因此后面还可以接着调用`then`方法。如果没有报错，则会跳过`catch`方法。

```javascript
const someAsyncThing = function() {
  return new Promise(function(resolve, reject) {
    // 下面一行会报错，因为x没有声明
    resolve(x + 2);
  });
};

someAsyncThing()
.catch(function(error) {
  console.log('oh no', error);  //函数没有return 默认是return undefined
})
.then(function() {
  console.log('carry on');
});
// oh no [ReferenceError: x is not defined]
// carry on
```



### Promise.prototype.finally()

`finally`方法用于指定不管 Promise 对象最后状态如何，都会执行的操作。

```javascript
promise
.then(result => {···})
.catch(error => {···})
.finally(() => {···});
```

`finally`方法的回调函数不接受任何参数，这意味着没有办法知道，前面的 Promise 状态到底是`fulfilled`还是`rejected`。这表明，`finally`方法里面的操作，应该是与状态无关的，不依赖于 Promise 的执行结果。



### Promise.all() 

`Promise.all`方法用于将多个 Promise 实例，包装成一个新的 Promise 实例。

```javascript
const p = Promise.all([p1, p2, p3]);

p.then([a, b, c] => {})
```

`p1`、`p2`、`p3`都是 Promise 实例，如果不是，就会先调用下面讲到的`Promise.resolve`方法，将参数转为 Promise 实例，再进一步处理。`Promise.all`方法的参数可以不是数组，但必须具有 Iterator 接口，且返回的每个成员都是 Promise 实例。

`p`的状态由`p1`、`p2`、`p3`决定，分成两种情况。

（1）只有`p1`、`p2`、`p3`的状态都变成`fulfilled`，`p`的状态才会变成`fulfilled`，此时`p1`、`p2`、`p3`的返回值组成一个数组，传递给`p`的回调函数。

（2）只要`p1`、`p2`、`p3`之中有一个被`rejected`，`p`的状态就变成`rejected`，此时第一个被`reject`的实例的返回值，会传递给`p`的回调函数。

注意，如果作为参数的 Promise 实例，自己定义了`catch`方法，那么它一旦被`rejected`，并不会触发`Promise.all()`的`catch`方法。

如果`p2`没有自己的`catch`方法，就会调用`Promise.all()`的`catch`方法。

```javascript
//p1会resolved
const p1 = new Promise((resolve, reject) => {	
  resolve('hello');
})
.then(result => result)
.catch(e => e);

//p2首先会rejected，但是p2有自己的catch方法，该方法返回的是一个新的 Promise 实例，p2指向的实际上是这个实例。
const p2 = new Promise((resolve, reject) => {
  throw new Error('报错了');
})
.then(result => result)
.catch(e => e);

Promise.all([p1, p2])
.then(result => console.log(result))
.catch(e => console.log(e));
// ["hello", Error: 报错了]
```



### Promise.race()

`Promise.race`方法同样是将多个 Promise 实例，包装成一个新的 Promise 实例。

```javascript
const p = Promise.race([p1, p2, p3]);
```

上面代码中，只要`p1`、`p2`、`p3`之中有一个实例率先改变状态，`p`的状态就跟着改变。那个率先改变的 Promise 实例的返回值，就传递给`p`的回调函数。

`Promise.race`方法的参数与`Promise.all`方法一样，如果不是 Promise 实例，就会先调用下面讲到的`Promise.resolve`方法，将参数转为 Promise 实例，再进一步处理。



### Promise.resolve() 

有时需要将现有对象转为 Promise 对象，`Promise.resolve`方法就起到这个作用。

```javascript
Promise.resolve('foo')
// 等价于
new Promise(resolve => resolve('foo'))
```

`Promise.resolve`方法的参数分成四种情况。

**（1）参数是一个 Promise 实例**

如果参数是 Promise 实例，那么`Promise.resolve`将不做任何修改、原封不动地返回这个实例。

**（2）参数是一个thenable对象**

`thenable`对象指的是具有`then`方法的对象，比如下面这个对象。

```javascript
let thenable = {
  then: function(resolve, reject) {
    resolve(42);
  }
};
```

`Promise.resolve`方法会将这个对象转为 Promise 对象，然后就立即执行`thenable`对象的`then`方法。

```javascript
let thenable = {
  then: function(resolve, reject) {
    resolve(42);
  }
};
//thenable对象的then方法执行后，对象p1的状态就变为resolved
let p1 = Promise.resolve(thenable);   
p1.then(function(value) {
  console.log(value);  // 42
});
```

**（3）参数不是具有then方法的对象，或根本就不是对象**

如果参数是一个原始值，或者是一个不具有`then`方法的对象，则`Promise.resolve`方法返回一个新的 Promise 对象，状态为`resolved`。

```javascript
const p = Promise.resolve('Hello');

p.then(function (s){
  console.log(s)
});
// Hello
```

**（4）不带有任何参数**

`Promise.resolve`方法允许调用时不带参数，直接返回一个`resolved`状态的 Promise 对象。

所以，如果希望得到一个 Promise 对象，比较方便的方法就是直接调用`Promise.resolve`方法。

```javascript
const p = Promise.resolve();

p.then(function () {
  // ...
});
```

需要注意的是，立即`resolve`的 Promise 对象，是在本轮“事件循环”（event loop）的结束时，而不是在下一轮“事件循环”的开始时。

```javascript
setTimeout(function () {		//下一轮事件循环开始时执行
  console.log('three');
}, 0);

Promise.resolve().then(function () {	//本轮事件循环结束时执行
  console.log('two');
});

console.log('one');		//立即执行

// one
// two
// three
```



### Promise.reject()

`Promise.reject(reason)`方法也会返回一个新的 Promise 实例，该实例的状态为`rejected`。

```javascript
const p = Promise.reject('出错了');
// 等同于
const p = new Promise((resolve, reject) => reject('出错了'))

p.then(null, function (s) {
  console.log(s)
});
// 出错了
```

注意，`Promise.reject()`方法的参数，会原封不动地作为`reject`的理由，变成后续方法的参数。这一点与`Promise.resolve`方法不一致。

```javascript
const thenable = {
  then(resolve, reject) {
    reject('出错了');
  }
};

Promise.reject(thenable)		
.catch(e => {		//e参数是上面的thenable这个对象 传进来
  console.log(e === thenable)
})
// true
```



### Promise.try()

```javascript
Promise.resolve().then(f)
```

上面的写法有一个缺点，就是如果`f`是同步函数，那么它会在本轮事件循环的末尾执行。

```javascript
const f = () => console.log('now');
Promise.resolve().then(f);
console.log('next');
// next
// now
```

上面代码中，函数`f`是同步的，但是用 Promise 包装了以后，就变成异步执行了。

那么有没有一种方法，让同步函数同步执行，异步函数异步执行，并且让它们具有统一的 API 呢？回答是可以的，并且还有两种写法。

第一种写法是用`async`函数来写。

```javascript
const f = () => console.log('now');
(async () => f())();		//没用使用await，还是同步函数
console.log('next');
// now
// next

//如果使用上await 就会变成异步， 因为await返回的是一个Promise对象，而Promise.resolve和Promise.reject都是异步方法，在事件循环末尾执行

const f = () => console.log('now');
(async () => {
    await f()			//使用了await，await下面的部分都变成异步了。 或者f函数是异步，就也是异步了
})();
console.log('next');
//next
//now
```

第二种写法是使用`new Promise()`。

```javascript
const f = () => console.log('now');
(
  () => new Promise(
    resolve => resolve(f())		//在作为参数传递给resolve()之前就执行了匿名函数，此时还是同步
  )
)();
console.log('next');
// now
// next
```

鉴于这是一个很常见的需求，所以现在有一个[提案](https://github.com/ljharb/proposal-promise-try)，提供`Promise.try`方法替代上面的写法。

```javascript
const f = () => console.log('now');
Promise.try(f);
console.log('next');
// now
// next
```

对于上面的`Promise.prototype.catch`抛出的异步错误和同步错误，我们可以配合`Promise.try`来捕获异步和同步错误很好的解决。

```js
database.users.get({id: userId})
.then(...)
.catch(...)			//捕获异步错误	

try {
  database.users.get({id: userId})
  .then(...)
  .catch(...)
} catch (e) {	//捕获同步错误
  // ...
}

//使用Promise.try()和promise.catch()来捕获所有同步和异步的错误。
Promise.try(database.users.get({id: userId}))
  .then(...)
  .catch(...)
```

事实上，`Promise.try`就是模拟`try`代码块，就像`promise.catch`模拟的是`catch`代码块。